Workbook

Sheet 统计表
A1: 序号 | B1: 抬头 | C1: 出货日期 | D1: 主体 | E1: 测试厂 | F1: 型号 | G1: 物料编码 | H1: 数量 | I1: 采购订单号 | J1: 单价 | K1: 备注 | L1: 10000900
A2: 1 | B2: HK Bitmain | C2: 44565 | D2: 世纪云芯 | E2: XJ | F2: BM1362AA | G2: Y09BM1362A00 | H2: 1441 | I2: 202201040015 | J2: 3.3
A3: 2 | B3: HK Bitmain | C3: 44565 | D3: 世纪云芯 | E3: XJ | F3: BM1362AC | G3: Y09BM1362C00 | H3: 139912 | I3: 202201040015 | J3: 3.3
A4: 3 | B4: HK Bitmain | C4: 44565 | D4: 世纪云芯 | E4: XJ | F4: BM1398BB | G4: Y09BM1398240 | H4: 439315 | I4: 202201040015 | J4: 6.1
A5: 4 | B5: HK Bitmain | C5: 44565 | D5: 世纪云芯 | E5: XJ | F5: BM1725AA | G5: Y09BM1725000 | H5: 154 | I5: 202201040015 | J5: 12
A6: 5 | B6: HK Bitmain | C6: 44565 | D6: 世纪云芯 | E6: XJ | F6: BM1746AA | G6: Y09BM1746010 | H6: 67 | I6: 202201040015 | J6: 81.65
A7: 6 | B7: HK Bitmain | C7: 44565 | D7: 智能云芯 | E7: XJ | F7: BM1684AE | G7: Y09BM1684440 | H7: 2250 | I7: 202201040002 | J7: 41.19
A8: 7 | B8: HK Bitmain | C8: 44566 | D8: 世纪云芯 | E8: XJ | F8: BM1746AA | G8: Y09BM1746010 | H8: 6319 | I8: 202201050010 | J8: 81.65
A9: 8 | B9: HK Bitmain | C9: 44566 | D9: 世纪云芯 | E9: 捷策创 | F9: BM1362AC | G9: Y09BM1362C00 | H9: 366684 | I9: 202201050011 | J9: 3.3
A10: 9 | B10: HK Bitmain | C10: 44566 | D10: 世纪云芯 | E10: 捷策创 | F10: BM1398BB | G10: Y09BM1398240 | H10: 1552171 | I10: 202201050012 | J10: 6.1 | K10: 发厦门
A11: 10 | B11: HK Bitmain | C11: 44567 | D11: 世纪云芯 | E11: XJ | F11: BM1362AA | G11: Y09BM1362A00 | H11: 5280 | I11: 202201060012 | J11: 3.3
A12: 11 | B12: HK Bitmain | C12: 44567 | D12: 世纪云芯 | E12: XJ | F12: BM1362AC | G12: Y09BM1362C00 | H12: 619229 | I12: 202201060012 | J12: 3.3
A13: 12 | B13: HK Bitmain | C13: 44567 | D13: 世纪云芯 | E13: XJ | F13: BM1362AI | G13: Y09BM1362110 | H13: 18407 | I13: 202201060012 | J13: 3.3
A14: 13 | B14: HK Bitmain | C14: 44567 | D14: 世纪云芯 | E14: XJ | F14: BM1489 | G14: Y09BM1489010 | H14: 185369 | I14: 202201060012 | J14: 6.22
A15: 14 | B15: HK Bitmain | C15: 44567 | D15: 世纪云芯 | E15: XJ | F15: BM1746AA | G15: Y09BM1746010 | H15: 194 | I15: 202201060012 | J15: 81.65
A16: 15 | B16: HK Bitmain | C16: 44568 | D16: 世纪云芯 | E16: 捷策创 | F16: BM1398BB | G16: Y09BM1398240 | H16: 92274 | I16: 202201070039 | J16: 6.1 | K16: 发厦门
A17: 16 | B17: HK Bitmain | C17: 44568 | D17: 智能云芯 | E17: XJ | F17: BM1684AE | G17: Y09BM1684440 | H17: 4555 | I17: 202201070004 | J17: 41.19
A18: 17 | C18: 44568 | D18: 世纪云芯 | E18: XJ | F18: BM1489 | G18: Y09BM1489010 | H18: 45198 | I18: 202201070004 | J18: 6.22
A19: 18 | C19: 44568 | D19: 世纪云芯 | E19: XJ | F19: BM1746AA | G19: Y09BM1746010 | H19: 154 | I19: 202201090001 | J19: 81.65
A20: 19 | C20: 44568 | D20: 世纪云芯 | E20: HN | F20: BM1362AJ | G20: Y09BM1362210 | H20: 9272 | I20: 202201090002 | J20: 3.3
A21: 20 | C21: 44568 | D21: 世纪云芯 | E21: Vtest | F21: BM1362AC | G21: Y09BM1362C00 | H21: 401661 | I21: 202201090003 | J21: 3.3
A22: 21 | C22: 44571 | D22: 世纪云芯 | E22: XJ | F22: BM1398BB | G22: Y09BM1398240 | H22: 91214 | I22: 202201110020 | J22: 6.1 | K22: 发厦门
A23: 22 | C23: 44571 | D23: 世纪云芯 | E23: XJ | F23: BM1489 | G23: Y09BM1489010 | H23: 155937 | I23: 202201110019 | J23: 6.22
A24: 23 | C24: 44571 | D24: 世纪云芯 | E24: XJ | F24: BM1746AA | G24: Y09BM1746010 | H24: 2004 | I24: 202201110019 | J24: 81.65
A25: 24 | C25: 44571 | D25: 智能云芯 | E25: XJ | F25: BM1684AE | G25: Y09BM1684440 | H25: 615 | I25: 202201110004 | J25: 41.19
A26: 25 | C26: 44573 | D26: 世纪云芯 | E26: XJ | F26: BM1362AK | G26: Y09BM1362310 | H26: 74602 | I26: 202201120086 | J26: 3.3 | L26: 朗华
A27: 26 | C27: 44573 | D27: 世纪云芯 | E27: XJ | F27: BM1489 | G27: Y09BM1489010 | H27: 16334 | I27: 202201120086 | J27: 6.22 | L27: 朗华
A28: 27 | C28: 44573 | D28: 世纪云芯 | E28: XJ | F28: BM1746AA | G28: Y09BM1746010 | H28: 7754 | I28: 202201120086 | J28: 81.65 | L28: 朗华
A29: 28 | C29: 44573 | D29: 世纪云芯 | E29: ASESH | F29: BM1362AC | G29: Y09BM1362C00 | H29: 1284009 | I29: 202201120087 | J29: 3.3 | L29: 世纪通
A30: 29 | C30: 44574 | D30: 世纪云芯 | E30: HN | F30: BM1489 | G30: Y09BM1489010 | H30: 98241 | I30: 202201140039 | J30: 6.22
A31: 30 | C31: 44574 | D31: 世纪云芯 | E31: SCK | F31: BM1764AB | G31: Y09BM1764010 | H31: 135 | I31: 202201150006 | J31: 3.44 | L31: 富森
A32: 31 | C32: 44575 | D32: 世纪云芯 | E32: CMC | F32: BM1398BB | G32: Y09BM1398240 | H32: 95142 | I32: 202201150003 | J32: 6.1 | L32: 朗华
A33: 32 | C33: 44575 | D33: 世纪云芯 | E33: XJ | F33: BM1362AC | G33: Y09BM1362C00 | H33: 50901 | I33: 202201150004 | J33: 3.3 | L33: 迅宇
A34: 33 | C34: 44575 | D34: 世纪云芯 | E34: XJ | F34: BM1489 | G34: Y09BM1489010 | H34: 10742 | I34: 202201150004 | J34: 6.22 | L34: 迅宇
A35: 34 | C35: 44575 | D35: 世纪云芯 | E35: XJ | F35: BM1746AA | G35: Y09BM1746010 | H35: 8874 | I35: 202201150004 | J35: 81.65 | L35: 迅宇
A36: 35 | C36: 44575 | D36: 智能云芯 | E36: XJ | F36: BM1684AE | G36: Y09BM1684440 | H36: 228 | I36: 202201150001 | J36: 41.19 | L36: 富森
A37: 36 | C37: 44578 | D37: 世纪云芯 | E37: XJ | F37: BM1489 | G37: Y09BM1489010 | H37: 5059 | I37: 202201180026 | J37: 6.22 | L37: 朗华
A38: 37 | C38: 44578 | D38: 世纪云芯 | E38: XJ | F38: BM1746AA | G38: Y09BM1746010 | H38: 7819 | I38: 202201180026 | J38: 81.65 | L38: 朗华
A39: 38 | C39: 44578 | D39: 世纪云芯 | E39: HN | F39: BM1489 | G39: Y09BM1489010 | H39: 414470 | I39: 202201180028 | J39: 6.22 | L39: 世纪通
A40: 39 | C40: 44578 | D40: 世纪云芯 | E40: SPILSZ | F40: BM1362AC | G40: Y09BM1362C00 | H40: 44 | I40: 202201190004 | J40: 3.3
...

Sheet 2月
A1: 序号 | B1: 抬头 | C1: 出货日期 | D1: 主体 | E1: 测试厂 | F1: 型号 | G1: 物料编码 | H1: 数量 | I1: 采购订单号 | J1: 单价 | K1: 备注 | L1: 10000900
A2: 1 | B2: HK Bitmain | C2: 44601 | D2: 世纪云芯 | E2: XJ | F2: BM1362AC | G2: Y09BM1362C00 | H2: 676329 | I2: 202202110005 | J2: 3.3 | L2: 朗华
A3: 2 | C3: 44601 | D3: 世纪云芯 | E3: XJ | F3: BM1362AI | G3: Y09BM1362110 | H3: 376910 | I3: 202202110005 | J3: 3.3 | L3: 朗华
A4: 3 | C4: 44601 | D4: 世纪云芯 | E4: XJ | F4: BM1489 | G4: Y09BM1489010 | H4: 2220909 | I4: 202202110005 | J4: 6.22 | L4: 朗华
A5: 4 | C5: 44601 | D5: 世纪云芯 | E5: XJ | F5: BM1746AA | G5: Y09BM1746010 | H5: 5274 | I5: 202202110005 | J5: 81.65 | L5: 朗华
A6: 5 | C6: 44601 | D6: 世纪云芯 | E6: 捷策创 | F6: BM1489 | G6: Y09BM1489010 | H6: 191079 | I6: 202202110006 | J6: 6.22 | L6: 世纪通
A7: 6 | C7: 44601 | D7: 世纪云芯 | E7: 捷策创 | F7: BM1362AK | G7: Y09BM1362310 | H7: 428328 | I7: 202202110006 | J7: 3.3 | L7: 世纪通
A8: 7 | C8: 44602 | D8: 世纪云芯 | E8: 捷策创 | F8: BM1362AK | G8: Y09BM1362310 | H8: 1041216 | I8: 202202110007 | J8: 3.3 | L8: 讯宇
A9: 8 | C9: 44603 | D9: 世纪云芯 | E9: 捷策创 | F9: BM1362AK | G9: Y09BM1362310 | H9: 621984 | I9: 202202120001 | J9: 3.3 | L9: 世纪通
A10: 9 | C10: 44603 | D10: 世纪云芯 | E10: XJ | F10: BM1362AK | G10: Y09BM1362310 | H10: 43832 | I10: 202202120002 | J10: 3.3 | L10: 朗华
A11: 10 | C11: 44603 | D11: 世纪云芯 | E11: XJ | F11: BM1398AC | G11: Y09BM1398350 | H11: 18487 | I11: 202202120002 | J11: 6.1 | L11: 朗华
A12: 11 | C12: 44603 | D12: 世纪云芯 | E12: XJ | F12: BM1398AD | G12: Y09BM1398D00 | H12: 1446 | I12: 202202120002 | J12: 6.1 | L12: 朗华
A13: 12 | C13: 44603 | D13: 世纪云芯 | E13: XJ | F13: BM1398BB | G13: Y09BM1398240 | H13: 52343 | I13: 202202120002 | J13: 6.1 | L13: 朗华
A14: 13 | C14: 44603 | D14: 世纪云芯 | E14: XJ | F14: BM1489 | G14: Y09BM1489010 | H14: 71239 | I14: 202202120002 | J14: 6.22 | L14: 朗华
A15: 14 | C15: 44603 | D15: 世纪云芯 | E15: XJ | F15: BM1746AA | G15: Y09BM1746010 | H15: 432 | I15: 202202120002 | J15: 81.65 | L15: 朗华
A16: 15 | C16: 44606 | D16: 世纪云芯 | E16: SCK | F16: BM1764AB | G16: Y09BM1764010 | H16: 269 | I16: 202202150003 | J16: 3.44 | L16: 富森
A17: 16 | C17: 44606 | D17: 世纪云芯 | E17: 捷策创 | F17: BM1489 | G17: Y09BM1489010 | H17: 146974 | I17: 202202150005 | J17: 6.22 | L17: 世纪通
A18: 17 | C18: 44606 | D18: 世纪云芯 | E18: 捷策创 | F18: BM1398BB | G18: Y09BM1398240 | H18: 302241 | I18: 202202150005 | J18: 6.1 | L18: 世纪通
A19: 18 | C19: 44606 | D19: 世纪云芯 | E19: 捷策创 | F19: BM1362AK | G19: Y09BM1362310 | H19: 538154 | I19: 202202150006 | J19: 3.3 | L19: 讯宇 | M19: 送深圳
A20: 19 | C20: 44606 | D20: 世纪云芯 | E20: 捷策创 | F20: BM1362AK | G20: Y09BM1362310 | H20: 429398 | I20: 202202150007 | J20: 3.3 | L20: 讯宇 | M20: 送厦门
A21: 20 | C21: 44606 | D21: 世纪云芯 | E21: XJ | F21: BM1362AC | G21: Y09BM1362C00 | H21: 101282 | I21: 202202150008 | J21: 3.3 | L21: 朗华
A22: 21 | C22: 44606 | D22: 世纪云芯 | E22: XJ | F22: BM1362AK | G22: Y09BM1362310 | H22: 42324 | I22: 202202150008 | J22: 3.3 | L22: 朗华
A23: 22 | C23: 44606 | D23: 世纪云芯 | E23: XJ | F23: BM1489 | G23: Y09BM1489010 | H23: 159990 | I23: 202202150008 | J23: 6.22 | L23: 朗华
A24: 23 | C24: 44606 | D24: 世纪云芯 | E24: XJ | F24: BM1362AK | G24: Y09BM1362310 | H24: 66449 | I24: 202202150008 | J24: 3.3 | L24: 朗华 | M24: 送厦门
A25: 24 | C25: 44608 | D25: 世纪云芯 | E25: SCK | F25: BM1366AB | G25: Y09BM1366120 | H25: 135 | I25: 202202170004 | J25: 4.72 | L25: 富森
A26: 25 | C26: 44608 | D26: 世纪云芯 | E26: 捷策创 | F26: BM1362AK | G26: Y09BM1362310 | H26: 418652 | I26: 202202170005 | J26: 3.3 | L26: 朗华
A27: 26 | C27: 44608 | D27: 世纪云芯 | E27: 捷策创 | F27: BM1362AK | G27: Y09BM1362310 | H27: 344922 | I27: 202202170006 | J27: 3.3 | L27: 朗华 | M27: 送厦门
A28: 27 | C28: 44608 | D28: 世纪云芯 | E28: XJ | F28: BM1362AI | G28: Y09BM1362110 | H28: 28954 | I28: 202202170007 | J28: 3.3 | L28: 世纪通
A29: 28 | C29: 44608 | D29: 世纪云芯 | E29: XJ | F29: BM1362AC | G29: Y09BM1362C00 | H29: 67770 | I29: 202202170007 | J29: 3.3 | L29: 世纪通
A30: 29 | C30: 44608 | D30: 世纪云芯 | E30: XJ | F30: BM1362AK | G30: Y09BM1362310 | H30: 26036 | I30: 202202170007 | J30: 3.3 | L30: 世纪通
A31: 30 | C31: 44608 | D31: 世纪云芯 | E31: XJ | F31: BM1362AK | G31: Y09BM1362310 | H31: 358444 | I31: 202202170007 | J31: 3.3 | L31: 世纪通 | M31: 送厦门
A32: 31 | C32: 44608 | D32: 世纪云芯 | E32: 捷策创 | F32: BM1489 | G32: Y09BM1489010 | H32: 199634 | I32: 202202170008 | J32: 6.22 | L32: 讯宇
A33: 32 | C33: 44609 | D33: 世纪云芯 | E33: 矽迈 | F33: BM1362AM | G33: Y09BM1362540 | H33: 617 | I33: 202202190001 | J33: 3.3 | L33: 富森
A34: 33 | C34: 44610 | D34: 世纪云芯 | E34: XJ | F34: BM1362AK | G34: Y09BM1362310 | H34: 614195 | I34: 202202190002 | J34: 3.3 | L34: 朗华
A35: 34 | C35: 44610 | D35: 世纪云芯 | E35: XJ | F35: BM1398BB | G35: Y09BM1398240 | H35: 45078 | I35: 202202190002 | J35: 6.1 | L35: 朗华
A36: 35 | C36: 44610 | D36: 世纪云芯 | E36: 捷策创 | F36: BM1398BB | G36: Y09BM1398240 | H36: 76430 | I36: 202202190003 | J36: 6.1 | L36: 朗华
A37: 36 | C37: 44610 | D37: 世纪云芯 | E37: 捷策创 | F37: BM1362AK | G37: Y09BM1362310 | H37: 408842 | I37: 202202190003 | J37: 3.3 | L37: 朗华
A38: 37 | C38: 44610 | D38: 世纪云芯 | E38: 捷策创 | F38: BM1362AK | G38: Y09BM1362310 | H38: 246021 | I38: 202202190004 | J38: 3.3 | L38: 朗华 | M38: 送厦门
A39: 38 | C39: 44613 | D39: 世纪云芯 | E39: XJ | F39: BM1489 | G39: Y09BM1489010 | H39: 99303 | I39: 202202220023 | J39: 6.22 | L39: 朗华
A40: 39 | C40: 44613 | D40: 世纪云芯 | E40: 捷策创 | F40: BM1362AC | G40: Y09BM1362C00 | H40: 415611 | I40: 202202220024 | J40: 3.3 | L40: 世纪通
...

Sheet 3月
A1: 序号 | B1: 抬头 | C1: 出货日期 | D1: 主体 | E1: 测试厂 | F1: 型号 | G1: 物料编码 | H1: 数量 | I1: 采购订单号 | J1: 单价 | K1: 备注 | L1: 10000900
A2: 1 | B2: HK Bitmain | C2: 44622 | D2: 世纪云芯 | E2: XJ | F2: BM1362AK | G2: Y09BM1362310 | H2: 234994 | I2: 202203030007 | J2: 3.3 | L2: 朗华
A3: 2 | B3: HK Bitmain | C3: 44622 | D3: 世纪云芯 | E3: XJ | F3: BM1362AI | G3: Y09BM1362110 | H3: 340298 | I3: 202203030007 | J3: 3.3 | L3: 朗华
A4: 3 | B4: HK Bitmain | C4: 44622 | D4: 世纪云芯 | E4: XJ | F4: BM1362AC | G4: Y09BM1362C00 | H4: 101823 | I4: 202203030007 | J4: 3.3 | L4: 朗华
A5: 4 | B5: HK Bitmain | C5: 44622 | D5: 世纪云芯 | E5: XJ | F5: BM1489 | G5: Y09BM1489010 | H5: 279689 | I5: 202203030007 | J5: 6.22 | L5: 朗华
A6: 5 | B6: HK Bitmain | C6: 44622 | D6: 世纪云芯 | E6: XJ | F6: BM1362AI | G6: Y09BM1362110 | H6: 746024 | I6: 202203030008 | J6: 3.3 | K6: 送厦门 | L6: 朗华
A7: 6 | B7: HK Bitmain | C7: 44622 | D7: 世纪云芯 | E7: XJ | F7: BM1362AC | G7: Y09BM1362C00 | H7: 254531 | I7: 202203030008 | J7: 3.3 | K7: 送厦门 | L7: 朗华
A8: 7 | B8: HK Bitmain | C8: 44622 | D8: 世纪云芯 | E8: 捷策创 | F8: BM1489 | G8: Y09BM1489010 | H8: 108861 | I8: 202203030009 | J8: 6.22 | L8: 朗华
A9: 8 | B9: HK Bitmain | C9: 44622 | D9: 世纪云芯 | E9: 捷策创 | F9: BM1398BB | G9: Y09BM1398240 | H9: 135144 | I9: 202203030009 | J9: 6.1 | L9: 朗华
A10: 9 | B10: HK Bitmain | C10: 44622 | D10: 世纪云芯 | E10: 捷策创 | F10: BM1362AK | G10: Y09BM1362310 | H10: 413055 | I10: 202203030009 | J10: 3.3 | L10: 朗华
A11: 10 | B11: HK Bitmain | C11: 44624 | D11: 世纪云芯 | E11: XJ | F11: BM1362AK | G11: Y09BM1362310 | H11: 165176 | I11: 202203050029 | J11: 3.3 | L11: 朗华
A12: 11 | B12: HK Bitmain | C12: 44624 | D12: 世纪云芯 | E12: XJ | F12: BM1362AC | G12: Y09BM1362C00 | H12: 226609 | I12: 202203050029 | J12: 3.3 | L12: 朗华
A13: 12 | B13: HK Bitmain | C13: 44624 | D13: 世纪云芯 | E13: XJ | F13: BM1362AI | G13: Y09BM1362110 | H13: 443586 | I13: 202203050029 | J13: 3.3 | L13: 朗华
A14: 13 | B14: HK Bitmain | C14: 44624 | D14: 世纪云芯 | E14: XJ | F14: BM1725AA | G14: Y09BM1725000 | H14: 14640 | I14: 202203050029 | J14: 12 | L14: 朗华
A15: 14 | B15: HK Bitmain | C15: 44624 | D15: 世纪云芯 | E15: 捷策创 | F15: BM1362AK | G15: Y09BM1362310 | H15: 381232 | I15: 202203050030 | J15: 3.3 | L15: 朗华
A16: 15 | B16: HK Bitmain | C16: 44624 | D16: 世纪云芯 | E16: 捷策创 | F16: BM1489 | G16: Y09BM1489010 | H16: 632906 | I16: 202203050030 | J16: 6.22 | L16: 朗华
A17: 16 | B17: HK Bitmain | C17: 44627 | D17: 世纪云芯 | E17: 捷策创 | F17: BM1489 | G17: Y09BM1489010 | H17: 375896 | I17: 202203080001 | J17: 6.22 | L17: 讯宇
A18: 17 | B18: HK Bitmain | C18: 44627 | D18: 世纪云芯 | E18: XJ | F18: BM1362AK | G18: Y09BM1362310 | H18: 400374 | I18: 202203080002 | J18: 3.3 | L18: 世纪通
A19: 18 | B19: HK Bitmain | C19: 44627 | D19: 世纪云芯 | E19: XJ | F19: BM1489 | G19: Y09BM1489010 | H19: 353142 | I19: 202203080003 | J19: 6.22 | L19: 世纪通
... A38: 37 | B38: HK Bitmain | C38: 44637 | D38: 世纪云芯 | E38: XJ | F38: BM1489 | G38: Y09BM1489010 | H38: 463116 | I38: 202203180013 | J38: 6.22 | L38: 朗华
A39: 38 | B39: HK Bitmain | C39: 44638 | D39: 世纪云芯 | E39: 捷策创 | F39: BM1362AC | G39: Y09BM1362C00 | H39: 322736 | I39: 202203200010 | J39: 3.3 | K39: HQ | L39: 朗华
A40: 39 | B40: HK Bitmain | C40: 44638 | D40: 世纪云芯 | E40: XJ | F40: BM1362AI | G40: Y09BM1362110 | H40: 570508 | I40: 202203200012 | J40: 3.3 | K40: YDF | L40: 朗华
A41: 40 | B41: HK Bitmain | C41: 44638 | D41: 世纪云芯 | E41: XJ | F41: BM1362AC | G41: Y09BM1362C00 | H41: 31101 | I41: 202203200012 | J41: 3.3 | K41: YDF | L41: 朗华
A42: 41 | B42: HK Bitmain | C42: 44638 | D42: 世纪云芯 | E42: XJ | F42: BM1489 | G42: Y09BM1489010 | H42: 246347 | I42: 202203200012 | J42: 6.22 | K42: YDF | L42: 朗华
A43: 42 | B43: HK Bitmain | C43: 44638 | D43: 世纪云芯 | E43: XJ | F43: BM1362AC | G43: Y09BM1362C00 | H43: 3811 | I43: 202203200011 | J43: 3.3 | K43: HQ | L43: 朗华
A44: 43 | B44: HK Bitmain | C44: 44638 | D44: 世纪云芯 | E44: XJ | F44: BM1362AI | G44: Y09BM1362110 | H44: 61730 | I44: 202203200011 | J44: 3.3 | K44: HQ | L44: 朗华
A45: 44 | B45: HK Bitmain | C45: 44638 | D45: 世纪云芯 | E45: XJ | F45: BM1362AC | G45: Y09BM1362C00 | H45: 19913 | I45: 202203200011 | J45: 3.3 | K45: HQ | L45: 朗华
A46: 45 | B46: HK Bitmain | C46: 44638 | D46: 世纪云芯 | E46: 捷策创 | F46: BM1362AJ | G46: Y09BM1362210 | H46: 475311 | I46: 202203200013 | J46: 3.3 | K46: YDF | L46: 朗华
A47: 46 | B47: HK Bitmain | C47: 44638 | D47: 世纪云芯 | E47: 捷策创 | F47: BM1366AB | G47: Y09BM1366120 | H47: 40680 | I47: 202203200013 | J47: 4.72 | K47: YDF | L47: 朗华
A48: 47 | B48: HK Bitmain | C48: 44638 | D48: 世纪云芯 | E48: 捷策创 | F48: BM1362AK | G48: Y09BM1362310 | H48: 751599 | I48: 202203200013 | J48: 3.3 | K48: YDF | L48: 朗华
A49: 48 | B49: HK Bitmain | C49: 44638 | D49: 世纪云芯 | E49: 捷策创 | F49: BM1362AK | G49: Y09BM1362310 | H49: 285480 | I49: 202203200013 | J49: 3.3 | K49: YDF | L49: 朗华
A50: 49 | B50: HK Bitmain | C50: 44638 | D50: 世纪云芯 | E50: 捷策创 | F50: BM1489 | G50: Y09BM1489010 | H50: 326414 | I50: 202203200013 | J50: 6.22 | K50: YDF | L50: 朗华
A51: 50 | B51: HK Bitmain | C51: 44641 | D51: 世纪云芯 | E51: 捷策创 | F51: BM1362AC | G51: Y09BM1362C00 | H51: 602565 | I51: 202203230001 | J51: 3.3 | L51: 朗华
A52: 52 | B52: HK Bitmain | C52: 44641 | D52: 世纪云芯 | E52: XJ | F52: BM1362AC | G52: Y09BM1362C00 | H52: 443620 | I52: 202203230002 | J52: 3.3 | L52: 世纪通
A53: 54 | B53: HK Bitmain | C53: 44641 | D53: 世纪云芯 | E53: XJ | F53: BM1362AI | G53: Y09BM1362110 | H53: 1297348 | I53: 202203230002 | J53: 3.3 | L53: 世纪通
A54: 56 | B54: HK Bitmain | C54: 44641 | D54: 世纪云芯 | E54: XJ | F54: BM1362AK | G54: Y09BM1362310 | H54: 161316 | I54: 202203230002 | J54: 3.3 | L54: 世纪通
A55: 57 | B55: HK Bitmain | C55: 44641 | D55: 世纪云芯 | E55: XJ | F55: BM1489 | G55: Y09BM1489010 | H55: 380756 | I55: 202203230002 | J55: 6.22 | L55: 世纪通
A56: 58 | B56: HK Bitmain | C56: 44642 | D56: 世纪云芯 | E56: 捷策创 | F56: BM1398BB | G56: Y09BM1398240 | H56: 215987 | I56: 202203230003 | J56: 6.1 | L56: 朗华
A57: 59 | B57: HK Bitmain | C57: 44642 | D57: 世纪云芯 | E57: XJ | F57: BM1362AK | G57: Y09BM1362310 | H57: 58567 | I57: 202203230004 | J57: 3.3 | L57: 世纪通
A58: 59 | B58: HK Bitmain | C58: 44642 | D58: 世纪云芯 | E58: XJ | F58: BM1489 | G58: Y09BM1489010 | H58: 118214 | I58: 202203230004 | J58: 6.22 | L58: 世纪通
...

Sheet 4月
A1: 序号 | B1: 抬头 | C1: 出货日期 | D1: 主体 | E1: 测试厂 | F1: 型号 | G1: 物料编码 | H1: 数量 | I1: 采购订单号 | J1: 单价 | K1: 备注 | L1: 10000900
A2: 1 | B2: HK Bitmain | C2: 44652 | D2: 世纪云芯 | E2: XJ | F2: BM1362AI | G2: Y09BM1362110 | H2: 723209 | I2: 202204020013 | J2: 2.71 | L2: 朗华
A3: 2 | B3: HK Bitmain | C3: 44652 | D3: 世纪云芯 | E3: XJ | F3: BM1362AC | G3: Y09BM1362C00 | H3: 78327 | I3: 202204020013 | J3: 2.71 | L3: 朗华
A4: 3 | B4: HK Bitmain | C4: 44652 | D4: 世纪云芯 | E4: XJ | F4: BM1362AC | G4: Y09BM1362C00 | H4: 61837 | I4: 202204020013 | J4: 2.71 | L4: 朗华
A5: 4 | B5: HK Bitmain | C5: 44652 | D5: 世纪云芯 | E5: XJ | F5: BM1489 | G5: Y09BM1489010 | H5: 345165 | I5: 202204020013 | J5: 7.51 | L5: 朗华
A6: 5 | B6: HK Bitmain | C6: 44653 | D6: 世纪云芯 | E6: 确安 | F6: BM1362AC | G6: Y09BM1362C00 | H6: 270130 | I6: 202204060004 | J6: 2.71 | L6: 朗华
A7: 6 | B7: HK Bitmain | C7: 44653 | D7: 世纪云芯 | E7: SCS | F7: BM1362AJ | G7: Y09BM1362210 | H7: 187163 | I7: 202204060005 | J7: 2.71 | L7: 朗华
A8: 7 | B8: HK Bitmain | C8: 44655 | D8: 世纪云芯 | E8: XJ | F8: BM1362AK | G8: Y09BM1362310 | H8: 3791246 | I8: 202204060017 | J8: 2.71 | L8: 朗华
A9: 8 | B9: HK Bitmain | C9: 44655 | D9: 世纪云芯 | E9: XJ | F9: BM1362AC | G9: Y09BM1362C00 | H9: 308273 | I9: 202204060017 | J9: 2.71 | L9: 朗华
A10: 9 | B10: HK Bitmain | C10: 44655 | D10: 世纪云芯 | E10: XJ | F10: BM1362AI | G10: Y09BM1362110 | H10: 1523285 | I10: 202204060017 | J10: 2.71 | L10: 朗华
A11: 10 | B11: HK Bitmain | C11: 44657 | D11: 世纪云芯 | E11: XJ | F11: BM1362AK | G11: Y09BM1362310 | H11: 5253 | I11: 202204060018 | J11: 2.71 | L11: 朗华
A12: 11 | B12: HK Bitmain | C12: 44652 | D12: 世纪云芯 | E12: 捷策创 | F12: BM1398BB | G12: Y09BM1398240 | H12: 109267 | I12: 202204070004 | J12: 6.1 | L12: 朗华
A13: 12 | B13: HK Bitmain | C13: 44652 | D13: 世纪云芯 | E13: 捷策创 | F13: BM1489 | G13: Y09BM1489010 | H13: 174437 | I13: 202204070004 | J13: 6.22 | L13: 朗华
... A36: 35 | B36: HK Bitmain | C36: 44664 | D36: 世纪云芯 | E36: XJ | F36: BM1489 | G36: Y09BM1489010 | H36: 54958 | I36: 202204150018 | J36: 7.51 | L36: 朗华
A37: 36 | B37: HK Bitmain | C37: 2022-04-14 | D37: 世纪云芯 | E37: spil | F37: BM1366AG | G37: Y09BM1366820 | H37: 4160 | I37: 202204150019 | J37: 4.54 | L37: 朗华
A38: 37 | B38: HK Bitmain | C38: 2022-04-14 | D38: 世纪云芯 | E38: JSCC | F38: BM1366AG | G38: Y09BM1366820 | H38: 4185 | I38: 202204150020 | J38: 4.54 | L38: 朗华
A39: 38 | B39: HK Bitmain | C39: 2022-04-14 | D39: 世纪云芯 | E39: JSCC | F39: BM1362AC | G39: Y09BM1362C00 | H39: 648073 | I39: 202204150020 | J39: 2.71 | L39: 朗华
A40: 39 | B40: HK Bitmain | C40: 2022-04-14 | D40: 世纪云芯 | E40: 捷策创 | F40: BM1362AC | G40: Y09BM1362C00 | H40: 665632 | I40: 202204150021 | J40: 2.71 | L40: 朗华
A41: 40 | B41: HK Bitmain | C41: 2022-04-14 | D41: 世纪云芯 | E41: 捷策创 | F41: BM1489 | G41: Y09BM1489010 | H41: 180476 | I41: 202204150021 | J41: 7.51 | L41: 朗华
A42: 41 | B42: HK Bitmain | C42: 2022-04-14 | D42: 世纪云芯 | E42: 捷策创 | F42: BM1366AG | G42: Y09BM1366820 | H42: 83214 | I42: 202204150021 | J42: 4.54 | L42: 朗华
A43: 42 | B43: HK Bitmain | C43: 2022-04-14 | D43: 世纪云芯 | E43: 无锡伟测 | F43: BM1362AK | G43: Y09BM1362310 | H43: 1067086 | I43: 202204150022 | J43: 2.71 | L43: 朗华
A44: 43 | B44: HK Bitmain | C44: 44666 | D44: 世纪云芯 | E44: XJ | F44: BM1362AK | G44: Y09BM1362310 | H44: 2001339 | I44: 202204180009 | J44: 2.71 | L44: 朗华
A45: 44 | B45: HK Bitmain | C45: 44666 | D45: 世纪云芯 | E45: XJ | F45: BM1362AI | G45: Y09BM1362110 | H45: 114266 | I45: 202204180009 | J45: 2.71 | L45: 朗华
A46: 45 | B46: HK Bitmain | C46: 44666 | D46: 世纪云芯 | E46: XJ | F46: BM1362AC | G46: Y09BM1362C00 | H46: 24219 | I46: 202204180009 | J46: 2.71 | L46: 朗华
A47: 46 | B47: HK Bitmain | C47: 44666 | D47: 世纪云芯 | E47: XJ | F47: BM1489 | G47: Y09BM1489010 | H47: 19179 | I47: 202204180009 | J47: 7.51 | L47: 朗华
A48: 47 | B48: HK Bitmain | C48: 44666 | D48: 世纪云芯 | E48: 无锡伟测 | F48: BM1362AK | G48: Y09BM1362310 | H48: 314883 | I48: 202204180010 | J48: 2.71 | L48: 朗华
A49: 48 | B49: HK Bitmain | C49: 44669 | D49: 世纪云芯 | E49: spilsz | F49: BM1366AG | G49: Y09BM1366820 | H49: 4160 | I49: 202204180011 | J49: 4.54 | L49: 朗华
A50: 49 | B50: HK Bitmain | C50: 44669 | D50: 世纪云芯 | E50: spilsz | F50: BM1366AB | G50: Y09BM1366120 | H50: 1986 | I50: 1004202204180029 | J50: 4.54 | L50: 朗华
A51: 50 | B51: HK Bitmain | C51: 44669 | D51: 世纪云芯 | E51: 捷策创 | F51: BM1366AG | G51: Y09BM1366820 | H51: 32851 | I51: 202204200006 | J51: 4.54 | L51: 朗华
A52: 51 | B52: HK Bitmain | C52: 44669 | D52: 世纪云芯 | E52: 捷策创 | F52: BM1366AB | G52: Y09BM1366120 | H52: 4168 | I52: 202204200006 | J52: 4.54 | L52: 朗华
A53: 52 | B53: HK Bitmain | C53: 44669 | D53: 世纪云芯 | E53: 捷策创 | F53: BM1398BB | G53: Y09BM1398240 | H53: 112366 | I53: 202204200006 | J53: 5.03 | L53: 朗华
A54: 53 | B54: HK Bitmain | C54: 44669 | D54: 世纪云芯 | E54: 湖南越摩 | F54: BM1366AH | G54: Y09BM1366930 | H54: 200 | I54: 1004202204180031 | J54: 4.54 | L54: 朗华
A55: 54 | B55: HK Bitmain | C55: 44669 | D55: 世纪云芯 | E55: spiltw | F55: BM1366AG | G55: Y09BM1366820 | H55: 9968 | I55: 1004202204180032 | J55: 4.54 | L55: 朗华
... A81: 79 | B81: HK Bitmain | C81: 44680 | D81: 世纪云芯 | E81: 湖南越摩 | F81: BM1366AG | G81: Y09BM1366820 | H81: 1998 | I81: 1004202204290013 | J81: 4.54 | L81: 朗华

Sheet 5月
A1: 序号 | B1: 抬头 | C1: 出货日期 | D1: 主体 | E1: 测试厂 | F1: 型号 | G1: 物料编码 | H1: 数量 | I1: 采购订单号 | J1: 单价 | K1: 备注 | L1: 10000900
A2: 1 | B2: HK Bitmain | C2: 44687 | D2: 世纪云芯 | E2: 捷策创 | F2: BM1398BB | G2: Y09BM1398240 | H2: 151626 | I2: 1004202205080001 | J2: 5.03 | L2: 朗华
A3: 2 | B3: HK Bitmain | C3: 44687 | D3: 世纪云芯 | E3: XJ | F3: BM1489 | G3: Y09BM1489010 | H3: 57480 | I3: 1004202205080002 | J3: 7.51 | L3: 朗华
A4: 3 | B4: HK Bitmain | C4: 44688 | D4: 世纪云芯 | E4: XJ | F4: BM1798AA | G4: Y09BM1798010 | H4: 393 | I4: 1004202205080002 | J4: 264.51 | L4: 朗华
A5: 4 | B5: HK Bitmain | C5: 44688 | D5: 世纪云芯 | E5: XJ | F5: BM1362AK | G5: Y09BM1362310 | H5: 2000510 | I5: 1004202205080002 | J5: 2.71 | L5: 朗华
A6: 5 | B6: HK Bitmain | C6: 44688 | D6: 世纪云芯 | E6: XJ | F6: BM1362AC | G6: Y09BM1362C00 | H6: 1767347 | I6: 1004202205080002 | J6: 2.71 | L6: 朗华
A7: 6 | B7: HK Bitmain | C7: 44688 | D7: 世纪云芯 | E7: XJ | F7: BM1362AI | G7: Y09BM1362110 | H7: 149730 | I7: 1004202205080002 | J7: 2.71 | L7: 朗华
A8: 7 | B8: HK Bitmain | C8: 44688 | D8: 世纪云芯 | E8: XJ | F8: BM1489 | G8: Y09BM1489010 | H8: 11915 | I8: 1004202205080002 | J8: 7.51 | L8: 朗华
A9: 8 | B9: HK Bitmain | C9: 44688 | D9: 世纪云芯 | E9: JSCC | F9: BM1366AG | G9: Y09BM1366820 | H9: 4061 | I9: 1004202205080003 | J9: 4.54 | L9: 朗华
A10: 9 | B10: HK Bitmain | C10: 44690 | D10: 世纪云芯 | E10: asekh | F10: BM1366AG | G10: Y09BM1366820 | H10: 4192 | I10: 1004202205100001 | J10: 4.54 | L10: 朗华

Sheet 5月（海南）
A1: 序号 | B1: 抬头 | C1: 出货日期 | D1: 主体 | E1: 测试厂 | F1: 型号 | G1: 物料编码 | H1: 数量 | I1: 采购订单号 | J1: 新PO | K1: 人民币单价 | L1: 10000900
A2: 1 | B2: 海南比特 | C2: 2022-05-09 | D2: 世纪云芯 | E2: SCK | F2: BM1366AH | G2: Y09BM1366930 | H2: 9 | J2: SZK202206100028 | K2: 34.193901 | L2: 朗华
A3: 2 | B3: 海南比特 | C3: 2022-05-09 | D3: 世纪云芯 | E3: SCK | F3: BM1366BA | G3: Y09BM1366340 | H3: 104735 | I3: SZK1004202205120002取消改入SZK202205130018 | J3: SZK202206100028 | K3: 34.193901 | L3: 朗华
A4: 3 | B4: 海南比特 | C4: 2022-05-09 | D4: 世纪云芯 | E4: XJ | F4: BM1798AA | G4: Y09BM1798010 | H4: 3673 | I4: SZK1004202205120003 | J4: SZK202206100029 | K4: 1992.209 | L4: 朗华
A5: 4 | B5: 海南比特 | C5: 44691 | D5: 世纪云芯 | E5: SCK | F5: BM1362AK | G5: Y09BM1362310 | H5: 601896 | I5: SZK1004202205120004 | J5: SZK202206100034 | K5: 20.410897 | L5: 朗华
A6: 5 | B6: 海南比特 | C6: 44692 | D6: 世纪云芯 | E6: 捷策创 | F6: BM1398BB | G6: Y09BM1398240 | H6: 97096 | I6: SZK1004202205120005 | J6: SZK202206100035 | K6: 37.884432 | L6: 朗华
A7: 6 | B7: 海南比特 | C7: 44692 | D7: 世纪云芯 | E7: 捷策创 | F7: BM1362AC | G7: Y09BM1362C00 | H7: 608798 | I7: SZK1004202205120006 | J7: SZK202206100037 | K7: 20.410897 | L7: 朗华
A8: 7 | B8: 海南比特 | C8: 44692 | D8: 世纪云芯 | E8: 捷策创 | F8: BM1362AC | G8: Y09BM1362C00 | H8: 595482 | I8: SZK1004202205120006 | J8: SZK202206100037 | K8: 20.410897 | L8: 朗华
A9: 8 | B9: 海南比特 | C9: 44692 | D9: 世纪云芯 | E9: 无锡伟测 | F9: BM1366AG | G9: Y09BM1366820 | H9: 15034 | I9: SZK1004202205120007 | J9: SZK202206100038 | K9: 34.193901 | L9: 朗华
A10: 9 | B10: 海南比特 | C10: 44692 | D10: 世纪云芯 | E10: 无锡伟测 | F10: BM1366AH | G10: Y09BM1366930 | H10: 91931 | I10: SZK1004202205120007 | J10: SZK202206100039 | K10: 34.193901 | L10: 朗华
A11: 11 | B11: 海南比特 | C11: 44693 | D11: 世纪云芯 | E11: spilsz | F11: BM1366AG | G11: Y09BM1366820 | H11: 31380 | I11: SZK202205130023 | J11: SZK202206100040 | K11: 34.193901 | L11: 朗华
A12: 12 | B12: 海南比特 | C12: 44694 | D12: 世纪云芯 | E12: XJ | F12: BM1362AK | G12: Y09BM1362310 | H12: 2000972 | I12: SZK202205130024 | J12: SZK202206100041 | K12: 20.410897 | L12: 朗华
A13: 13 | B13: 海南比特 | C13: 44694 | D13: 世纪云芯 | E13: XJ | F13: BM1362AB | G13: Y09BM1362B00 | H13: 1243 | I13: SZK202205130024 | J13: SZK202206100041 | K13: 20.410897 | L13: 朗华
A14: 14 | B14: 海南比特 | C14: 44694 | D14: 世纪云芯 | E14: XJ | F14: BM1362AC | G14: Y09BM1362C00 | H14: 438454 | I14: SZK202205130024 | J14: SZK202206100041 | K14: 20.410897 | L14: 朗华
A15: 15 | B15: 海南比特 | C15: 44694 | D15: 世纪云芯 | E15: XJ | F15: BM1362AI | G15: Y09BM1362110 | H15: 7597 | I15: SZK202205130024 | J15: SZK202206100041 | K15: 20.410897 | L15: 朗华
A16: 16 | B16: 海南比特 | C16: 44694 | D16: 世纪云芯 | E16: XJ | F16: BM1362AA | G16: Y09BM1362A00 | H16: 2210 | I16: SZK202205130024 | J16: SZK202206100041 | K16: 20.410897 | L16: 朗华
... A27: 27 | B27: 海南比特 | C27: 44699 | D27: 世纪云芯 | E27: SCK | F27: BM1366AH | G27: Y09BM1366930 | H27: 154 | I27: SZK202205190007 | J27: SZK202206100047 | K27: 34.193901 | L27: 世纪通
A28: 28 | B28: 海南比特 | C28: 44699 | D28: 世纪云芯 | E28: 捷策创 | F28: BM1489 | G28: Y09BM1489010 | H28: 212548 | I28: SZK202205190008/改成SZK202205250030PO | J28: SZK202206100048 | K28: 56.563039 | L28: 世纪通 | M28: 物流改了报关价格；重新下PO入库
A29: 29 | B29: 海南比特 | C29: 44699 | D29: 世纪云芯 | E29: 捷策创 | F29: BM1362AK | G29: Y09BM1362310 | H29: 1042992 | I29: SZK202205190008 | J29: SZK202206100048 | K29: 20.410897 | L29: 世纪通
A30: 30 | B30: 海南比特 | C30: 44699 | D30: 世纪云芯 | E30: XJ | F30: BM1362AC | G30: Y09BM1362C00 | H30: 187795 | I30: SZK202205190009 | J30: SZK202206100049 | K30: 20.410897 | L30: 世纪通
A31: 31 | B31: 海南比特 | C31: 44699 | D31: 世纪云芯 | E31: XJ | F31: BM1362AI | G31: Y09BM1362110 | H31: 18090 | I31: SZK202205190009 | J31: SZK202206100049 | K31: 20.410897 | L31: 世纪通
A32: 32 | B32: 海南比特 | C32: 44699 | D32: 世纪云芯 | E32: XJ | F32: BM1798AA | G32: Y09BM1798010 | H32: 25 | I32: SZK202205190009 | J32: SZK202206100049 | K32: 1992.209 | L32: 世纪通
A33: 33 | B33: 海南比特 | C33: 44701 | D33: 世纪云芯 | E33: 捷策创 | F33: BM1489 | G33: Y09BM1489010 | H33: 76510 | I33: SZK202205220002 | J33: SZK202206100050 | K33: 56.563039 | L33: 朗华
A34: 34 | B34: 海南比特 | C34: 44701 | D34: 世纪云芯 | E34: 捷策创 | F34: BM1489 | G34: Y09BM1489010 | H34: 101438 | I34: SZK202205220002 | J34: SZK202206100050 | K34: 56.563039 | L34: 朗华
A35: 35 | B35: 海南比特 | C35: 44701 | D35: 世纪云芯 | E35: 捷策创 | F35: BM1398BB | G35: Y09BM1398240 | H35: 101279 | I35: SZK202205220002 | J35: SZK202206100050 | K35: 37.884432 | L35: 朗华
A36: 36 | B36: 海南比特 | C36: 44701 | D36: 世纪云芯 | E36: 捷策创 | F36: BM1362AK | G36: Y09BM1362310 | H36: 2261903 | I36: SZK202205220002 | J36: SZK202206100050 | K36: 20.410897 | L36: 朗华
A37: 37 | B37: 海南比特 | C37: 44701 | D37: 世纪云芯 | E37: 伟测 | F37: BM1362AK | G37: Y09BM1362310 | H37: 2071337 | I37: SZK202205220002 | J37: SZK202206100051 | K37: 20.410897 | L37: 朗华 | M37: 物流把供应商名称写错了
A38: 38 | B38: 海南比特 | C38: 44701 | D38: 世纪云芯 | E38: ASEKH | F38: BM1366AB | G38: Y09BM1366120 | H38: 2191 | I38: SZK202205220003 | J38: SZK202206100052 | K38: 34.193901 | L38: 朗华
A39: 39 | B39: 海南比特 | C39: 44701 | D39: 世纪云芯 | E39: XJ | F39: BM1362AK | G39: Y09BM1362310 | H39: 1802463 | I39: SZK202205220004 | J39: SZK202206100053 | K39: 20.410897 | L39: 朗华
A40: 40 | B40: 海南比特 | C40: 44701 | D40: 世纪云芯 | E40: XJ | F40: BM1362AC | G40: Y09BM1362C00 | H40: 106484 | I40: SZK202205220004 | J40: SZK202206100053 | K40: 20.410897 | L40: 朗华
A41: 41 | B41: 海南比特 | C41: 44701 | D41: 世纪云芯 | E41: XJ | F41: BM1362AI | G41: Y09BM1362110 | H41: 67930 | I41: SZK202205220004 | J41: SZK202206100053 | K41: 20.410897 | L41: 朗华
A42: 42 | B42: 海南比特 | C42: 44701 | D42: 世纪云芯 | E42: XJ | F42: BM1489 | G42: Y09BM1489010 | H42: 111256 | I42: SZK202205220004 | J42: SZK202206100053 | K42: 56.563039 | L42: 朗华
A43: 43 | B43: 海南比特 | C43: 44704 | D43: 世纪云芯 | E43: 捷策创 | F43: BM1489 | G43: Y09BM1489010 | H43: 114902 | I43: SZK202205240014 | J43: SZK202206100055 | K43: 56.563039 | L43: 朗华
A44: 44 | B44: 海南比特 | C44: 44704 | D44: 世纪云芯 | E44: XJ | F44: BM1362AK | G44: Y09BM1362310 | H44: 2004927 | I44: SZK202205240015 | J44: SZK202206100056 | K44: 20.410897 | L44: 朗华
A45: 45 | B45: 海南比特 | C45: 44704 | D45: 世纪云芯 | E45: XJ | F45: BM1489 | G45: Y09BM1489010 | H45: 15812 | I45: SZK202205240015 | J45: SZK202206100056 | K45: 56.563039 | L45: 朗华
A46: 46 | B46: 海南比特 | C46: 44704 | D46: 世纪云芯 | E46: 捷策创 | F46: BM1366AG | G46: Y09BM1366820 | H46: 51945 | I46: SZK202205240016 | J46: SZK202206100057 | K46: 34.193901 | L46: 朗华
A47: 47 | B47: 海南比特 | C47: 44704 | D47: 世纪云芯 | E47: 捷策创 | F47: BM1489 | G47: Y09BM1489010 | H47: 49891 | I47: SZK202205240016 | J47: SZK202206100057 | K47: 56.563039 | L47: 朗华
A48: 48 | B48: 海南比特 | C48: 44704 | D48: 世纪云芯 | E48: 湖南越摩 | F48: BM1366AG | G48: Y09BM1366820 | H48: 572 | I48: SZK202205240017 | J48: SZK202206100058 | K48: 34.193901 | L48: 朗华
A49: 49 | B49: 海南比特 | C49: 44704 | D49: 世纪云芯 | E49: 无锡伟测 | F49: BM1362AC | G49: Y09BM1362C00 | H49: 425137 | I49: SZK202205240018 | J49: SZK202206100059 | K49: 20.410897 | L49: 朗华
... A78: 17 | B78: 海南比特 | C78: 44718 | D78: 世纪云芯 | E78: SCK | F78: BM1362AK | G78: Y09BM1362310 | H78: 482174 | I78: SZK202206070014 | J78: SZK202206090041 | K78: 19.366046 | L78: 朗华

Sheet 6月（海南）
A1: 序号 | B1: 抬头 | C1: 出货日期 | D1: 主体 | E1: 测试厂 | F1: 型号 | G1: 物料编码 | H1: 数量 | I1: 采购订单号 | J1: 新PO | K1: 单价 | L1: 10000900
A2: 1 | B2: 海南比特 | C2: 44713 | D2: 世纪云芯 | E2: 湖南越摩 | F2: BM1366AG | G2: Y09BM1366820 | H2: 1193 | I2: SZK202206070003 | J2: SZK202206090030 | K2: 33.845968 | L2: 朗华
A3: 2 | B3: 海南比特 | C3: 44713 | D3: 世纪云芯 | E3: asekh | F3: BM1366AB | G3: Y09BM1366120 | H3: 231 | I3: SZK202206070004 | J3: SZK202206090031 | K3: 33.845968 | L3: 朗华
A4: 3 | B4: 海南比特 | C4: 44713 | D4: 世纪云芯 | E4: XJ | F4: BM1366AG | G4: Y09BM1366820 | H4: 30875 | I4: SZK202206070005 | J4: SZK202206090032 | K4: 33.845968 | L4: 朗华
A5: 4 | B5: 海南比特 | C5: 44713 | D5: 世纪云芯 | E5: 捷策创 | F5: BM1366AG | G5: Y09BM1366820 | H5: 361316 | I5: SZK202206070006 | J5: SZK202206090033 | K5: 33.845968 | L5: 朗华
A6: 5 | B6: 海南比特 | C6: 44713 | D6: 世纪云芯 | E6: SCK | F6: BM1366AH | G6: Y09BM1366930 | H6: 77 | I6: SZK202206070007 | J6: SZK202206090034 | K6: 33.845968 | L6: 朗华
A7: 6 | B7: 海南比特 | C7: 44714 | D7: 世纪云芯 | E7: XJ | F7: BM1362AK | G7: Y09BM1362310 | H7: 2000945 | I7: SZK202206070008 | J7: SZK202206090035 | K7: 20.219624 | L7: 朗华
A8: 7 | B8: 海南比特 | C8: 44714 | D8: 世纪云芯 | E8: XJ | F8: BM1366AG | G8: Y09BM1366820 | H8: 115724 | I8: SZK202206070008 | J8: SZK202206090035 | K8: 33.845968 | L8: 朗华
A9: 8 | B9: 海南比特 | C9: 44714 | D9: 世纪云芯 | E9: 捷策创 | F9: BM1366AG | G9: Y09BM1366820 | H9: 514389 | I9: SZK202206070009 | J9: SZK202206090036 | K9: 33.845968 | L9: 朗华
A10: 9 | B10: 海南比特 | C10: 44714 | D10: 世纪云芯 | E10: TF | F10: BM1366AB | G10: Y09BM1366120 | H10: 996 | I10: SZK202206070010 | J10: SZK202206090037 | K10: 33.845968 | L10: 朗华
A11: 10 | B11: 海南比特 | C11: 44718 | D11: 世纪云芯 | E11: spilsz | F11: BM1366AG | G11: Y09BM1366820 | H11: 4193 | J11: SZK202206090038 | K11: 33.845968 | L11: 朗华
A12: 11 | B12: 海南比特 | C12: 44718 | D12: 世纪云芯 | E12: XJ | F12: BM1362AK | G12: Y09BM1362310 | H12: 1001415 | I12: SZK202206070012 | J12: SZK202206090039 | K12: 20.219624 | L12: 朗华
A13: 12 | B13: 海南比特 | C13: 44718 | D13: 世纪云芯 | E13: 捷策创 | F13: BM1366AG | G13: Y09BM1366820 | H13: 618016 | I13: SZK202206070013 | J13: SZK202206090040 | K13: 33.845968 | L13: 朗华
A14: 13 | B14: 海南比特 | C14: 44718 | D14: 世纪云芯 | E14: SCK | F14: BM1727AA | G14: Y09BM1727010 | H14: 12066 | J14: SZK202206090027 | K14: 29.582181 | L14: 朗华
A15: 14 | B15: 海南比特 | C15: 44718 | D15: 世纪云芯 | E15: SCK | F15: BM2042AA | G15: Y09BM2042010 | H15: 12046 | J15: SZK202206090027 | K15: 29.582181 | L15: 朗华
A16: 15 | B16: 海南比特 | C16: 44718 | D16: 世纪云芯 | E16: SCK | F16: BM2110AA | G16: Y09BM2110010 | H16: 11728 | J16: SZK202206090027 | K16: 29.582181 | L16: 朗华
A17: 16 | B17: 海南比特 | C17: 44718 | D17: 世纪云芯 | E17: SCK | F17: BM2130AA | G17: Y09BM2130010 | H17: 11944 | J17: SZK202206090027 | K17: 29.582181 | L17: 朗华
A18: 17 | B18: 海南比特 | C18: 44718 | D18: 世纪云芯 | E18: SCK | F18: BM1362AK | G18: Y09BM1362310 | H18: 482174 | I18: SZK202206070014 | J18: SZK202206090041 | K18: 19.366046 | L18: 朗华
A19: 18 | B19: 海南比特 | C19: 44719 | D19: 世纪云芯 | E19: SCK | F19: BM1766AA | G19: Y09BM1766010 | H19: 39627 | J19: SZK202206090042 | K19: 29.582181 | L19: 世纪通
A20: 19 | B20: 海南比特 | C20: 44719 | D20: 世纪云芯 | E20: SCK | F20: BM2042AA | G20: Y09BM2042010 | H20: 27734 | J20: SZK202206090042 | K20: 29.582181 | L20: 世纪通
A21: 20 | B21: 海南比特 | C21: 44719 | D21: 世纪云芯 | E21: SCK | F21: BM2110AA | G21: Y09BM2110010 | H21: 27014 | J21: SZK202206090042 | K21: 29.582181 | L21: 世纪通
A22: 21 | B22: 海南比特 | C22: 44719 | D22: 世纪云芯 | E22: SCK | F22: BM2130AA | G22: Y09BM2130010 | H22: 27470 | J22: SZK202206090042 | K22: 29.582181 | L22: 世纪通
A23: 22 | B23: 海南比特 | C23: 44720 | D23: 世纪云芯 | E23: XJ | F23: BM1362AK | G23: Y09BM1362310 | H23: 2008347 | J23: SZK202206090043 | K23: 20.219624 | L23: 朗华
A24: 23 | B24: 海南比特 | C24: 44720 | D24: 世纪云芯 | E24: XJ | F24: BM1366AG | G24: Y09BM1366820 | H24: 980875 | J24: SZK202206090043 | K24: 33.845968 | L24: 朗华
A25: 24 | B25: 海南比特 | C25: 44720 | D25: 世纪云芯 | E25: XJ | F25: BM1398BB | G25: Y09BM1398240 | H25: 863 | J25: SZK202206090043 | K25: 38.463171 | L25: 朗华
A26: 25 | B26: 海南比特 | C26: 44720 | D26: 世纪云芯 | E26: XJ | F26: BM1746AA | G26: Y09BM1746010 | H26: 905 | J26: SZK202206090043 | K26: 450.19529 | L26: 朗华
A27: 26 | B27: 海南比特 | C27: 44720 | D27: 世纪云芯 | E27: 捷策创 | F27: BM1366AG | G27: Y09BM1366820 | H27: 650342 | J27: SZK202206090044 | K27: 33.845968 | L27: 迅宇
A28: 27 | B28: 海南比特 | C28: 44720 | D28: 世纪云芯 | E28: 捷策创 | F28: BM1362AK | G28: Y09BM1362310 | H28: 1013212 | J28: SZK202206090044 | K28: 20.219624 | L28: 迅宇
A29: 28 | B29: 海南比特 | C29: 44721 | D29: 世纪云芯 | E29: SCK | F29: BM1727AA | G29: Y09BM1727010 | H29: 30175 | J29: SZK202206130021 | K29: 29.582181 | L29: 世纪通
A30: 29 | B30: 海南比特 | C30: 44721 | D30: 世纪云芯 | E30: SCK | F30: BM1766AA | G30: Y09BM1766010 | H30: 30001 | J30: SZK202206130021 | K30: 29.582181 | L30: 世纪通
... A50: 49 | B50: 海南比特 | C50: 44725 | D50: 世纪云芯 | E50: XJ | F50: BM1746AA | G50: Y09BM1746010 | H50: 3920 | J50: SZK202206140018 | K50: 450.19529 | L50: 朗华
A51: 50 | B51: 海南比特 | C51: 44701 | D51: 世纪云芯 | E51: ASEKH | F51: BM1366AB | G51: Y09BM1366120 | H51: 2190 | I51: SZK202206100052 | J51: SZK202207080002 | K51: 34.193901 | L51: 朗华 | M51: 5月份报关进品的一直被卡关，实物6月份才进来
A52: 51 | B52: 海南比特 | C52: 44727 | D52: 世纪云芯 | E52: SCK | F52: BM2042AA | G52: Y09BM2042010 | H52: 30124 | J52: SZK202206170036 | K52: 29.5822 | L52: 朗华
A53: 52 | B53: 海南比特 | C53: 44727 | D53: 世纪云芯 | E53: 捷策创 | F53: BM1398BB | G53: Y09BM1398240 | H53: 14296 | J53: SZK202206170038 | K53: 38.4632 | L53: 朗华
A54: 53 | B54: 海南比特 | C54: 44727 | D54: 世纪云芯 | E54: 捷策创 | F54: BM1362AK | G54: Y09BM1362310 | H54: 402497 | J54: SZK202206170038 | K54: 20.2196 | L54: 朗华
A55: 54 | B55: 海南比特 | C55: 44727 | D55: 世纪云芯 | E55: XJ | F55: BM1362AK | G55: Y09BM1362310 | H55: 4001973 | J55: SZK202206170039 | K55: 20.2196 | L55: 朗华
A56: 55 | B56: 海南比特 | C56: 44727 | D56: 世纪云芯 | E56: 伟测 | F56: BM1362AK | G56: Y09BM1362310 | H56: 2360723 | J56: SZK202206170040 | K56: 20.2196 | L56: 朗华
A57: 56 | B57: 海南比特 | C57: 44729 | D57: 世纪云芯 | E57: ASESH | F57: BM1366AH | G57: Y09BM1366930 | H57: 208 | J57: SZK202206200001 | K57: 33.846 | L57: 朗华 | M57: 4.43
A58: 57 | B58: 海南比特 | C58: 44729 | D58: 世纪云芯 | E58: 伟测 | F58: BM1362AK | G58: Y09BM1362310 | H58: 1511564 | J58: SZK202206200002 | K58: 20.2196 | L58: 朗华 | M58: 2.65
A59: 58 | B59: 海南比特 | C59: 44729 | D59: 世纪云芯 | E59: XJ | F59: BM1362AK | G59: Y09BM1362310 | H59: 3742238 | J59: SZK202206200003 | K59: 20.2196 | L59: 朗华 | M59: 2.65
...

Sheet 7月（香港）
A1: 序号 | B1: 抬头 | C1: 出货日期 | D1: 主体 | E1: 测试厂 | F1: 型号 | G1: 物料编码 | H1: 数量 | I1: 采购订单号 | J1: 新PO | K1: 单价 | L1: 10000900
A2: 1 | B2: 香港比特 | C2: 44755 | D2: 世纪云芯 | E2: spilsz | F2: BM1366AL | G2: Y09BM1366D10 | H2: 835031 | J2: SZK202207180010 | K2: 4.75 | L2: 朗华
A3: 2 | B3: 香港比特 | C3: 44755 | D3: 世纪云芯 | E3: 捷策创 | F3: BM1362AA | G3: Y09BM1362A00 | H3: 242499 | J3: SZK202207180004 | K3: 2.68 | L3: 朗华
A4: 3 | B4: 香港比特 | C4: 44755 | D4: 世纪云芯 | E4: 捷策创 | F4: BM1489 | G4: Y09BM1489010 | H4: 114 | J4: SZK202207180004 | K4: 7.31 | L4: 朗华
A5: 4 | B5: 香港比特 | C5: 44755 | D5: 世纪云芯 | E5: 捷策创 | F5: BM1362AK | G5: Y09BM1362310 | H5: 71956 | J5: SZK202207180004 | K5: 2.68 | L5: 朗华
A6: 5 | B6: 香港比特 | C6: 44755 | D6: 世纪云芯 | E6: ASEKH | F6: BM1366AG | G6: Y09BM1366820 | H6: 2183 | J6: SZK202207180005 | K6: 4.86 | L6: 朗华
A7: 6 | B7: 香港比特 | C7: 44755 | D7: 世纪云芯 | E7: SCK | F7: BM1366AG | G7: Y09BM1366820 | H7: 477229 | J7: SZK202207180006 | K7: 4.86 | L7: 朗华
A8: 7 | B8: 香港比特 | C8: 44755 | D8: 世纪云芯 | E8: SCK | F8: BM1366AH | G8: Y09BM1366930 | H8: 996 | J8: SZK202207180006 | K8: 4.86 | L8: 朗华
A9: 8 | B9: 香港比特 | C9: 44756 | D9: 世纪云芯 | E9: SCK | F9: BM1366AG | G9: Y09BM1366820 | H9: 207985 | J9: SZK202207180007 | K9: 4.75 | L9: 讯宇
A10: 9 | B10: 香港比特 | C10: 44756 | D10: 世纪云芯 | E10: SCK | F10: BM1362BD | G10: Y09BM1362D40 | H10: 683015 | J10: SZK202207180007 | K10: 2.57 | L10: 世纪通
A11: 10 | B11: 香港比特 | C11: 44757 | D11: 世纪云芯 | E11: SPILSZ | F11: BM1366AL | G11: Y09BM1366D10 | H11: 12489 | J11: SZK202207180011 | K11: 4.86 | L11: 讯宇
A12: 11 | B12: 香港比特 | C12: 44757 | D12: 世纪云芯 | E12: 捷策创 | F12: BM1362AK | G12: Y09BM1362310 | H12: 214513 | J12: SZK202207180008 | K12: 2.68 | L12: 朗华
A13: 12 | B13: 香港比特 | C13: 2022-07-16 | D13: 世纪云芯 | E13: XJ | F13: BM1798AA | G13: Y09BM1798010 | H13: 500 | J13: SZK202207180027 | K13: 261.94 | L13: 朗华
A14: 13 | B14: 香港比特 | C14: 2022-07-16 | D14: 世纪云芯 | E14: XJ | F14: BM1798AA | G14: Y09BM1798010 | H14: 200 | J14: SZK202207180027 | K14: 261.94 | L14: 朗华
A15: 14 | B15: 香港比特 | C15: 2022-07-17 | D15: 世纪云芯 | E15: XJ | F15: BM1798AA | G15: Y09BM1798010 | H15: 600 | J15: SZK202207180028 | K15: 261.94 | L15: 朗华
A16: 15 | B16: 香港比特 | C16: 2022-07-18 | D16: 世纪云芯 | E16: XJ | F16: BM1798AA | G16: Y09BM1798010 | H16: 800 | J16: SZK202207180029 | K16: 261.94 | L16: 朗华
A17: 16 | B17: 香港比特 | C17: 2022-07-18 | D17: 世纪云芯 | E17: 捷策创 | F17: BM1362AK | G17: Y09BM1362310 | H17: 677817 | J17: SZK202207180030 | K17: 2.68 | L17: 朗华
A18: 17 | B18: 香港比特 | C18: 2022-07-18 | D18: 世纪云芯 | E18: 捷策创 | F18: BM1362AK | G18: Y09BM1362310 | H18: 156522 | J18: SZK202207180030 | K18: 2.68 | L18: 朗华
A19: 插入（花姐下的） | B19: 香港比特 | C19: 44755 | D19: 世纪云芯 | E19: WINSTEK | F19: BM1366AL | G19: Y09BM1366D10 | H19: 1333 | J19: SZK202207200013 | K19: 4.86
A20: 18 | B20: 香港比特 | C20: 44762 | D20: 世纪云芯 | E20: 捷策创 | F20: BM1362AA | G20: Y09BM1362A00 | H20: 54096 | J20: SZK202207200022 | K20: 2.68 | L20: 世纪通 | M20: SZK202208020059
A21: 19 | B21: 香港比特 | C21: 44762 | D21: 世纪云芯 | E21: 捷策创 | F21: BM1362AC | G21: Y09BM1362C00 | H21: 37899 | J21: SZK202207200022 | K21: 2.68 | L21: 世纪通 | M21: SZK202208020059
A22: 20 | B22: 香港比特 | C22: 44762 | D22: 世纪云芯 | E22: 捷策创 | F22: BM1398BB | G22: Y09BM1398240 | H22: 656680 | J22: SZK202207200022 | K22: 4.28 | L22: 世纪通 | M22: SZK202208020059
A23: 21 | B23: 香港比特 | C23: 44762 | D23: 世纪云芯 | E23: SCK | F23: BM1727AA | G23: Y09BM1727010 | H23: 77 | J23: SZK202207200023 | K23: 3.51 | L23: 讯宇
A24: 22 | B24: 香港比特 | C24: 44762 | D24: 世纪云芯 | E24: XJ | F24: BM1798AA | G24: Y09BM1798010 | H24: 1400 | J24: SZK202207200023 | K24: 261.94 | L24: 讯宇
A25: 23 | B25: 香港比特 | C25: 44763 | D25: 世纪云芯 | E25: SCK | F25: BM1366AG | G25: Y09BM1366820 | H25: 4198 | J25: SZK202207210009 | K25: 4.86 | L25: 讯宇
A26: 24 | B26: 香港比特 | C26: 44763 | D26: 世纪云芯 | E26: XJ | F26: BM1798AA | G26: Y09BM1798010 | H26: 1000 | J26: SZK202207210010 | K26: 261.94 | L26: 讯宇
A27: 25 | B27: 香港比特 | C27: 44764 | D27: 世纪云芯 | E27: XJ | F27: BM1366AG | G27: Y09BM1366820 | H27: 237765 | J27: SZK202207230001 | K27: 4.86 | L27: 朗华
A28: 26 | B28: 香港比特 | C28: 44764 | D28: 世纪云芯 | E28: XJ | F28: BM1366AL | G28: Y09BM1366D10 | H28: 237865 | J28: SZK202207230001 | K28: 4.86 | L28: 朗华
A29: 27 | B29: 香港比特 | C29: 44764 | D29: 世纪云芯 | E29: XJ | F29: BM1366AG | G29: Y09BM1366820 | H29: 589893 | J29: SZK202207230001 | K29: 4.86 | L29: 朗华
A30: 28 | B30: 香港比特 | C30: 44764 | D30: 世纪云芯 | E30: XJ | F30: BM1798AA | G30: Y09BM1798010 | H30: 600 | J30: SZK202207230001 | K30: 261.94 | L30: 朗华
A31: 29 | B31: 香港比特 | C31: 44764 | D31: 世纪云芯 | E31: spil | F31: BM1798AB | G31: Y09BM1798110 | H31: 631 | J31: SZK202207250001 | K31: 261.94 | L31: 朗华 | M31: SZK202208100013
A32: 30 | B32: 香港比特 | C32: 44764 | D32: 世纪云芯 | E32: JSCC | F32: BM1366AG | G32: Y09BM1366820 | H32: 130310 | J32: SZK202207230002 | K32: 4.86 | L32: 朗华
A33: 31 | B33: 香港比特 | C33: 44764 | D33: 世纪云芯 | E33: JSCC | F33: BM1366AL | G33: Y09BM1366D10 | H33: 1225200 | J33: SZK202207230002 | K33: 4.86 | L33: 朗华
A34: 32 | B34: 香港比特 | C34: 44764 | D34: 世纪云芯 | E34: 捷策创 | F34: BM1398BB | G34: Y09BM1398240 | H34: 499575 | J34: SZK202207230003 | K34: 4.28 | L34: 讯宇
A35: 33 | B35: 香港比特 | C35: 44764 | D35: 智能云芯 | E35: XJ | F35: BM1684AE | G35: Y09BM1684440 | H35: 2229 | J35: ICK202207250001 | K35: 58.86 | L35: 朗华
A36: 34 | B36: 香港比特 | C36: 44767 | D36: 世纪云芯 | E36: 捷策创 | F36: BM1398BB | G36: Y09BM1398240 | H36: 788496 | J36: SZK202207260003 | K36: 4.28
A37: 35 | B37: 香港比特 | C37: 44767 | D37: 世纪云芯 | E37: XJ | F37: BM1366AG | G37: Y09BM1366820 | H37: 629693 | J37: SZK202207260004 | K37: 4.86 | L37: 世纪通
A38: 36 | B38: 香港比特 | C38: 44767 | D38: 世纪云芯 | E38: XJ | F38: BM1366AL | G38: Y09BM1366D10 | H38: 217395 | J38: SZK202207260004 | K38: 4.86 | L38: 世纪通
A39: 37 | B39: 香港比特 | C39: 44767 | D39: 世纪云芯 | E39: XJ | F39: BM1798AA | G39: Y09BM1798010 | H39: 172 | J39: SZK202207260004 | K39: 261.94 | L39: 世纪通
A40: 38 | B40: 香港比特 | C40: 44767 | D40: 世纪云芯 | E40: spilsz | F40: BM1366AH | G40: Y09BM1366930 | H40: 254 | J40: SZK202207260005 | K40: 4.86 | L40: 世纪通
...

Sheet 2023（香港）
A1: 序号 | B1: 抬头 | C1: 出货日期 | D1: 主体 | E1: 测试厂 | F1: 型号 | G1: 物料编码 | H1: 数量 | I1: 新PO | J1: 发料外协 | K1: 10000900 | L1: 单价
A2: 1 | B2: chanhua | C2: 45212 | D2: 香港比特 | E2: WX-HN | F2: BM1366AL | G2: =VLOOKUP(F2,编码对账表!C:D,2,0) | H2: 159277 | I2: HKK202310160002 | K2: CHANHUA PTE. LTD. | L2: 4.070077
A3: 2 | B3: 福建湛华 | C3: 45212 | D3: 香港比特 | E3: 世纪 | F3: BM1368PA | G3: =VLOOKUP(F3,编码对账表!C:D,2,0) | H3: 250 | I3: HKK202310170001 | L3: 6.97512
A4: 3 | B4: chanhua | C4: 45233 | D4: 香港比特 | E4: WX-HN | F4: BM1366AL | G4: =VLOOKUP(F4,编码对账表!C:D,2,0) | H4: 94986 | I4: HKK202311090001 | J4: 泰国群光 | K4: CHANHUA PTE. LTD. | L4: 4.07
A5: 4 | B5: chanhua | C5: 45238 | D5: 香港比特 | E5: XJ | F5: BM1366BP | G5: =VLOOKUP(F5,编码对账表!C:D,2,0) | H5: 812102 | I5: HKK202311160002 | J5: 印尼奥海 | K5: CHANHUA PTE. LTD. | L5: 4.07
A6: 5 | B6: chanhua | C6: 45244 | D6: 香港比特 | E6: XJ | F6: BM1366BP | G6: =VLOOKUP(F6,编码对账表!C:D,2,0) | H6: 109666 | I6: HKK202311230006 | J6: 泰国群光 | K6: CHANHUA PTE. LTD. | L6: 4.07
A7: 6 | B7: chanhua | C7: 45243 | D7: 香港比特 | E7: XJ | F7: BM1366BP | G7: =VLOOKUP(F7,编码对账表!C:D,2,0) | H7: 1021095 | I7: HKK202311230007 | J7: 印尼奥海 | K7: CHANHUA PTE. LTD. | L7: 4.07
A8: 7 | B8: chanhua | C8: 45251 | D8: 香港比特 | E8: XJ | F8: BM1366BP | G8: =VLOOKUP(F8,编码对账表!C:D,2,0) | H8: 429228 | I8: HKK202311230008 | J8: 泰国群光 | K8: CHANHUA PTE. LTD. | L8: 4.07
A9: 8 | B9: chanhua | C9: 45252 | D9: 香港比特 | E9: XJ | F9: BM1366BP | G9: =VLOOKUP(F9,编码对账表!C:D,2,0) | H9: 181661 | I9: HKK202311230009 | J9: 泰国群光 | K9: CHANHUA PTE. LTD. | L9: 4.07
A10: 9 | B10: chanhua | C10: 45251 | D10: 香港比特 | E10: XJ | F10: BM1366BP | G10: =VLOOKUP(F10,编码对账表!C:D,2,0) | H10: 51657 | I10: HKK202311230010 | J10: 印尼奥海 | K10: CHANHUA PTE. LTD. | L10: 4.07
A11: 10 | B11: chanhua | C11: 45254 | D11: 香港比特 | E11: XJ | F11: BM1366BP | G11: =VLOOKUP(F11,编码对账表!C:D,2,0) | H11: 1007680 | I11: HKK202312010001 | J11: 印尼奥海 | K11: CHANHUA PTE. LTD. | L11: 4.07
A12: 11 | B12: chanhua | C12: 45254 | D12: 香港比特 | E12: NJ-VT | F12: BM1366BP | G12: =VLOOKUP(F12,编码对账表!C:D,2,0) | H12: 93348 | I12: HKK202312010003 | J12: 印尼奥海 | K12: CHANHUA PTE. LTD. | L12: 4.07
A13: 12 | B13: chanhua | C13: 45254 | D13: 香港比特 | E13: XJ | F13: BM1366AL | G13: =VLOOKUP(F13,编码对账表!C:D,2,0) | H13: 178297 | I13: HKK202312010002 | J13: 印尼奥海 | K13: CHANHUA PTE. LTD. | L13: 4.07
A14: 13 | B14: chanhua | C14: 45254 | D14: 香港比特 | E14: WX-HN | F14: BM1366AL | G14: =VLOOKUP(F14,编码对账表!C:D,2,0) | H14: 544692 | I14: HKK202312010004 | J14: 印尼奥海 | K14: CHANHUA PTE. LTD. | L14: 4.07
A15: 14 | B15: chanhua | C15: 45257 | D15: 香港比特 | E15: NJ-VT | F15: BM1366AL | G15: =VLOOKUP(F15,编码对账表!C:D,2,0) | H15: 96852 | I15: HKK202312010005 | J15: 印尼奥海 | K15: CHANHUA PTE. LTD. | L15: 4.07
... A47: 46 | B47: chanhua | C47: 45289 | D47: 香港比特 | E47: SPILSZ | F47: BM1368PB | G47: =VLOOKUP(F47,编码对账表!C:D,2,0) | H47: 198288 | I47: HKK202401050008 | J47: 泰国益权 | K47: CHANHUA PTE. LTD. | L47: 4.3949

Sheet 2024（香港）
A1: 序号 | B1: 抬头 | C1: 出货日期 | D1: 主体 | E1: 测试厂 | F1: 型号 | G1: 物料编码 | H1: 数量 | I1: 新PO | J1: 发料外协 | K1: 10000900 | L1: 单价 | M1: SO
A2: 1 | B2: chanhua | C2: 45301 | D2: 香港比特 | E2: XJ | F2: BM1368AA | G2: =VLOOKUP(F2,编码对账表!C:D,2,0) | H2: 162222 | I2: HKK202401170010 | J2: 印尼奥海 | K2: CHANHUA PTE. LTD. | L2: 5.428
A3: 2 | B3: chanhua | C3: 45302 | D3: 香港比特 | E3: JSCC | F3: BM1368PB | G3: =VLOOKUP(F3,编码对账表!C:D,2,0) | H3: 885687 | I3: HKK202401170003 | J3: 印尼奥海 | K3: CHANHUA PTE. LTD. | L3: 4.3949
A4: 3 | B4: chanhua | C4: 45303 | D4: 香港比特 | E4: NJ-VT | F4: BM1366AL | G4: =VLOOKUP(F4,编码对账表!C:D,2,0) | H4: 7335 | I4: HKK202401170004 | J4: 印尼奥海 | K4: CHANHUA PTE. LTD. | L4: 4.0649
A5: 4 | B5: chanhua | C5: 45303 | D5: 香港比特 | E5: XJ | F5: BM1368AA | G5: =VLOOKUP(F5,编码对账表!C:D,2,0) | H5: 124762 | I5: HKK202401170005 | J5: 印尼奥海 | K5: CHANHUA PTE. LTD. | L5: 5.428
A6: 5 | B6: chanhua | C6: 45303 | D6: 香港比特 | E6: SPIL | F6: BM1368PB | G6: =VLOOKUP(F6,编码对账表!C:D,2,0) | H6: 2201734 | I6: HKK202401170006 | J6: 印尼奥海 | K6: CHANHUA PTE. LTD. | L6: 4.3949
A7: 6 | B7: chanhua | C7: 45303 | D7: 香港比特 | E7: WXHN | F7: BM1368PB | G7: =VLOOKUP(F7,编码对账表!C:D,2,0) | H7: 1766492 | I7: HKK202401170007 | J7: 泰国益权 | K7: CHANHUA PTE. LTD. | L7: 4.3949
A8: 7 | B8: chanhua | C8: 45303 | D8: 香港比特 | E8: XJ | F8: BM1368AA | G8: =VLOOKUP(F8,编码对账表!C:D,2,0) | H8: 162754 | I8: HKK202401170008 | J8: 泰国群光 | K8: CHANHUA PTE. LTD. | L8: 5.428
A9: 8 | B9: chanhua | C9: 45304 | D9: 香港比特 | E9: NJ-VT | F9: BM1366AL | G9: =VLOOKUP(F9,编码对账表!C:D,2,0) | H9: 108869 | I9: HKK202401170009 | J9: 泰国益权 | K9: CHANHUA PTE. LTD. | L9: 4.0649
A10: 9 | B10: 香港比特 | C10: 45310 | D10: 香港比特 | E10: 世纪云芯 | F10: BM1366AG | G10: =VLOOKUP(F10,编码对账表!C:D,2,0) | H10: 1402815 | I10: HKK202401190002 | J10: WXHN | K10: CHANHUA PTE. LTD. | L10: 5.0841
A11: 10 | B11: 香港比特 | C11: 45310 | D11: 香港比特 | E11: 世纪云芯 | F11: BM1366AL | G11: =VLOOKUP(F11,编码对账表!C:D,2,0) | H11: 1580851 | I11: HKK202401190002 | J11: WXHN | K11: CHANHUA PTE. LTD. | L11: 5.0841
A12: 11 | B12: 香港比特 | C12: 45310 | D12: 香港比特 | E12: 世纪云芯 | F12: BM1489 | G12: =VLOOKUP(F12,编码对账表!C:D,2,0) | H12: 173351 | I12: HKK202401190003 | J12: XJ | K12: CHANHUA PTE. LTD. | L12: 7.3261
A13: 12 | B13: chanhua | C13: 45306 | D13: 香港比特 | E13: WXHN | F13: BM1366AL | G13: =VLOOKUP(F13,编码对账表!C:D,2,0) | H13: 128377 | I13: HKK202401240001 | J13: 泰国益权 | K13: CHANHUA PTE. LTD. | L13: 4.0649
... A27: 26 | B27: chanhua | C27: 45317 | D27: 香港比特 | E27: XJ | F27: BM1368PB | G27: =VLOOKUP(F27,编码对账表!C:D,2,0) | H27: 388608 | I27: HKK202402020034 | J27: 泰国益权 | K27: CHANHUA PTE. LTD. | L27: 4.3949
A28: 27 | B28: chanhua | C28: 45317 | D28: 新加坡比特 | E28: WX-HN | F28: BM1368PB | G28: =VLOOKUP(F28,编码对账表!C:D,2,0) | H28: 1328315 | I28: 202402020002 | J28: 泰国ONETEC | L28: 4.3949
A29: 28 | B29: chanhua | C29: 45320 | D29: 香港比特 | E29: WX-HN | F29: BM1366AL | G29: =VLOOKUP(F29,编码对账表!C:D,2,0) | H29: 381192 | I29: HKK202402020035 | J29: 印尼奥海 | K29: CHANHUA PTE. LTD. | L29: 4.0649
A30: 29 | B30: chanhua | C30: 45320 | D30: 香港比特 | E30: XJ | F30: BM1368AA | G30: =VLOOKUP(F30,编码对账表!C:D,2,0) | H30: 1413717 | I30: HKK202402020036 | J30: 印尼奥海 | K30: CHANHUA PTE. LTD. | L30: 5.428
A31: 30 | B31: chanhua | C31: 45320 | D31: 香港比特 | E31: JSCC | F31: BM1368PB | G31: =VLOOKUP(F31,编码对账表!C:D,2,0) | H31: 1225823 | I31: HKK202402020037 | J31: 泰国益权 | K31: CHANHUA PTE. LTD. | L31: 4.3949
A32: 31 | B32: chanhua | C32: 45322 | D32: 香港比特 | E32: WX-HN | F32: BM1368PB | G32: =VLOOKUP(F32,编码对账表!C:D,2,0) | H32: 783344 | I32: HKK202402020038 | J32: 泰国益权 | K32: CHANHUA PTE. LTD. | L32: 4.3949
A33: 32 | B33: chanhua | C33: 45322 | D33: 香港比特 | E33: XJ | F33: BM1366AL | G33: =VLOOKUP(F33,编码对账表!C:D,2,0) | H33: 348383 | I33: HKK202402020039 | J33: 泰国益权 | K33: CHANHUA PTE. LTD. | L33: 4.0649
A34: 33 | B34: chanhua | C34: 45322 | D34: 香港比特 | E34: XJ | F34: BM1368AA | G34: =VLOOKUP(F34,编码对账表!C:D,2,0) | H34: 1127272 | I34: HKK202402020040 | J34: 泰国群光 | K34: CHANHUA PTE. LTD. | L34: 5.428
A35: 34 | B35: chanhua | C35: 45323 | D35: 香港比特 | E35: SPILSZ | F35: BM1368PB | G35: =VLOOKUP(F35,编码对账表!C:D,2,0) | H35: 79597 | I35: HKK202402080001 | J35: 泰国益权 | K35: CHANHUA PTE. LTD. | L35: 4.3949
A36: 35 | B36: chanhua | C36: 45324 | D36: 香港比特 | E36: XJ | F36: BM1368AA | G36: =VLOOKUP(F36,编码对账表!C:D,2,0) | H36: 183951 | I36: HKK202402080002 | J36: 泰国群光 | K36: CHANHUA PTE. LTD. | L36: 5.428
A37: 36 | B37: chanhua | C37: 45324 | D37: 香港比特 | E37: XJ | F37: BM1368AA | G37: =VLOOKUP(F37,编码对账表!C:D,2,0) | H37: 451567 | I37: HKK202402080003 | J37: 印尼奥海 | K37: CHANHUA PTE. LTD. | L37: 5.428
A38: 37 | B38: chanhua | C38: 45324 | D38: 香港比特 | E38: WX-HN | F38: BM1368AA | G38: =VLOOKUP(F38,编码对账表!C:D,2,0) | H38: 1243730 | I38: HKK202402080004 | J38: 印尼奥海 | K38: CHANHUA PTE. LTD. | L38: 5.428
A39: 38 | B39: chanhua | C39: 45326 | D39: 香港比特 | E39: SPILSZ | F39: BM1368PB | G39: =VLOOKUP(F39,编码对账表!C:D,2,0) | H39: 69308 | I39: HKK202402080005 | J39: 泰国群光 | K39: CHANHUA PTE. LTD. | L39: 4.3949
A40: 39 | B40: chanhua | C40: 45326 | D40: 香港比特 | E40: SPILSZ | F40: BM1368PV | G40: =VLOOKUP(F40,编码对账表!C:D,2,0) | H40: 287712 | I40: HKK202402080006 | J40: 泰国群光 | K40: CHANHUA PTE. LTD. | L40: 4.3949
... A145: 144 | B145: chanhua | C145: 45379 | D145: 新加坡比特 | E145: JSCC | F145: BM1368PB | G145: =VLOOKUP(F145,编码对账表!C:D,2,0) | H145: 1778068 | I145: 202404030004 | J145: 泰国onetec | K145: CHANHUA PTE. LTD. | L145: 5.4206
A146: 145 | B146: chanhua | C146: 45358 | D146: chanhua | E146: 世纪云芯 | F146: BM1370AA | G146: =VLOOKUP(F146,编码对账表!C:D,2,0) | H146: 154 | I146: 202404070001 | J146: SCK | K146: CHANHUA PTE. LTD. | L146: 5.2301 | M146: 已接收
A147: 145 | B147: chanhua | C147: 45359 | D147: chanhua | E147: 世纪云芯 | F147: BM1370AA | G147: =VLOOKUP(F147,编码对账表!C:D,2,0) | H147: 2165 | I147: 202404070002 | J147: JSCC | K147: CHANHUA PTE. LTD. | L147: 5.2301 | M147: 已接收
A148: 146 | B148: chanhua | C148: 45369 | D148: chanhua | E148: 世纪云芯 | F148: BM1370AA | G148: =VLOOKUP(F148,编码对账表!C:D,2,0) | H148: 2456 | I148: 202404070003 | J148: ASE-CL | K148: CHANHUA PTE. LTD. | L148: 5.2301 | M148: 已接收
A149: 147 | B149: chanhua | C149: 45369 | D149: chanhua | E149: 世纪云芯 | F149: BM1370AA | G149: =VLOOKUP(F149,编码对账表!C:D,2,0) | H149: 2400 | I149: 202404070004 | J149: ASE-KH | K149: CHANHUA PTE. LTD. | L149: 5.2301 | M149: 已接收
A150: 148 | B150: chanhua | C150: 45371 | D150: chanhua | E150: 世纪云芯 | F150: BM1370AA | G150: =VLOOKUP(F150,编码对账表!C:D,2,0) | H150: 546 | I150: 202404070005 | J150: ASE-KH | K150: CHANHUA PTE. LTD. | L150: 5.2301 | M150: 已接收
A151: 149 | B151: chanhua | C151: 45371 | D151: chanhua | E151: 世纪云芯 | F151: BM1370AA | G151: =VLOOKUP(F151,编码对账表!C:D,2,0) | H151: 77 | I151: 202404070006 | J151: SCK | K151: CHANHUA PTE. LTD. | L151: 5.2301 | M151: 已接收
A152: 150 | B152: chanhua | C152: 45362 | D152: 新加坡比特 | E152: WXHN | F152: BM1368PV | G152: =VLOOKUP(F152,编码对账表!C:D,2,0) | H152: 69521 | I152: 202404070001 | J152: 墨西哥欧陆通 | K152: CHANHUA PTE. LTD. | L152: 5.4206
A153: 151 | B153: chanhua | C153: 45385 | D153: 香港比特 | E153: JSCC | F153: BM1368PB | G153: =VLOOKUP(F153,编码对账表!C:D,2,0) | H153: 230097 | I153: HKK202404110001 | J153: 印尼奥海 | K153: CHANHUA PTE. LTD. | L153: 5.4206
A154: 152 | B154: chanhua | C154: 45385 | D154: 香港比特 | E154: JSCC | F154: BM1368PV | G154: =VLOOKUP(F154,编码对账表!C:D,2,0) | H154: 135339 | I154: HKK202404110001 | J154: 印尼奥海 | K154: CHANHUA PTE. LTD. | L154: 5.4206
A155: 153 | B155: chanhua | C155: 45385 | D155: 香港比特 | E155: NJ-VT | F155: BM1368PB | G155: =VLOOKUP(F155,编码对账表!C:D,2,0) | H155: 200336 | I155: HKK202404110002 | J155: 印尼奥海 | K155: CHANHUA PTE. LTD. | L155: 5.4206
A156: 154 | B156: chanhua | C156: 45385 | D156: 香港比特 | E156: SPILSZ | F156: BM1368PB | G156: =VLOOKUP(F156,编码对账表!C:D,2,0) | H156: 47534 | I156: HKK202404110003 | J156: 印尼奥海 | K156: CHANHUA PTE. LTD. | L156: 5.4206
A157: 155 | B157: chanhua | C157: 45385 | D157: 香港比特 | E157: WXHN | F157: BM2382AA | G157: =VLOOKUP(F157,编码对账表!C:D,2,0) | H157: 339080 | I157: HKK202404110004 | J157: 印尼奥海 | K157: CHANHUA PTE. LTD. | L157: 3.5251
...

Sheet 2025（香港） 
A1: 序号 | B1: 抬头 | C1: 出货日期 | D1: 主体 | E1: 测试厂 | H1: 型号 | I1: 物料编码 | J1: 数量 | K1: 新PO | L1: SO | M1: 发料外协 | N1: 币种 | O1: 单价 | P1: 对比 | Q1: 是否已出 | R1: 问题 | S1: 解决方法
A2: 1 | B2: chanhua | C2: 45666 | D2: 新加坡比特 | E2: SPILSZ | H2: BM1370BC | I2: =VLOOKUP(H2,编码对账表!C:D,2,0) | J2: 9751 | K2: 202501130015 | L2: 1403250113115210 | M2: 印尼奥海 | N2: CHANHUA PTE. LTD. | O2: 8.3272 | P2: =VLOOKUP(L2,[3]BHSC_销售订单明细报表_060825!$E$1:$E$65536,1,FALSE)
A3: 2 | B3: chanhua | C3: 45659 | D3: 新加坡比特 | E3: JSCC | H3: BM1370PA | I3: =VLOOKUP(H3,编码对账表!C:D,2,0) | J3: 1478593 | K3: 202501130015 | L3: 1403250113115210 | M3: 印尼奥海 | N3: CHANHUA PTE. LTD. | O3: 8.3272 | P3: =VLOOKUP(L3,[3]BHSC_销售订单明细报表_060825!$E$1:$E$65536,1,FALSE)
A4: 3 | B4: chanhua | C4: 45662 | D4: 新加坡比特 | E4: SPILSZ | H4: BM1370PA | I4: =VLOOKUP(H4,编码对账表!C:D,2,0) | J4: 1288200 | K4: 202501130015 | L4: 1403250113115210 | M4: 印尼奥海 | N4: CHANHUA PTE. LTD. | O4: 8.3272 | P4: =VLOOKUP(L4,[3]BHSC_销售订单明细报表_060825!$E$1:$E$65536,1,FALSE)
A5: 4 | B5: chanhua | C5: 45661 | D5: 新加坡比特 | E5: TFME | H5: BM1370PA | I5: =VLOOKUP(H5,编码对账表!C:D,2,0) | J5: 50079 | K5: 202501130015 | L5: 1403250113115210 | M5: 印尼奥海 | N5: CHANHUA PTE. LTD. | O5: 8.3272 | P5: =VLOOKUP(L5,[3]BHSC_销售订单明细报表_060825!$E$1:$E$65536,1,FALSE)
A6: 5 | B6: chanhua | C6: 45667 | D6: 新加坡比特 | E6: JSCC | H6: BM1370PM | I6: =VLOOKUP(H6,编码对账表!C:D,2,0) | J6: 1806656 | K6: 202501130015 | L6: 1403250113115210 | M6: 印尼奥海 | N6: CHANHUA PTE. LTD. | O6: 8.3272 | P6: =VLOOKUP(L6,[3]BHSC_销售订单明细报表_060825!$E$1:$E$65536,1,FALSE)
A7: 6 | B7: chanhua | C7: 45659 | D7: 新加坡比特 | E7: JSCC | H7: BM1370BC | I7: =VLOOKUP(H7,编码对账表!C:D,2,0) | J7: 369502 | K7: 202501130014 | L7: 1403250113115226 | M7: 泰国群光 | N7: CHANHUA PTE. LTD. | O7: 8.3272 | P7: =VLOOKUP(L7,[3]BHSC_销售订单明细报表_060825!$E$1:$E$65536,1,FALSE)
A8: 7 | B8: chanhua | C8: 45666 | D8: 新加坡比特 | E8: SPILSZ | H8: BM1370BC | I8: =VLOOKUP(H8,编码对账表!C:D,2,0) | J8: 717013 | K8: 202501130014 | L8: 1403250113115226 | M8: 泰国群光 | N8: CHANHUA PTE. LTD. | O8: 8.3272 | P8: =VLOOKUP(L8,[3]BHSC_销售订单明细报表_060825!$E$1:$E$65536,1,FALSE)
A9: 8 | B9: chanhua | C9: 45664 | D9: 新加坡比特 | E9: JSCC | H9: BM1370PA | I9: =VLOOKUP(H9,编码对账表!C:D,2,0) | J9: 676339 | K9: 202501130014 | L9: 1403250113115226 | M9: 泰国群光 | N9: CHANHUA PTE. LTD. | O9: 8.3272 | P9: =VLOOKUP(L9,[3]BHSC_销售订单明细报表_060825!$E$1:$E$65536,1,FALSE)
A10: 9 | B10: chanhua | C10: 45666 | D10: 新加坡比特 | E10: SPILSZ | H10: BM1370PA | I10: =VLOOKUP(H10,编码对账表!C:D,2,0) | J10: 950000 | K10: 202501130014 | L10: 1403250113115226 | M10: 泰国群光 | N10: CHANHUA PTE. LTD. | O10: 8.3272 | P10: =VLOOKUP(L10,[3]BHSC_销售订单明细报表_060825!$E$1:$E$65536,1,FALSE)
A11: 10 | B11: chanhua | C11: 45662 | D11: 新加坡比特 | E11: SPILSZ | H11: BM1370BC | I11: =VLOOKUP(H11,编码对账表!C:D,2,0) | J11: 125952 | K11: 202501130013 | L11: 1403250113115247 | M11: 泰国ONETEC | N11: CHANHUA PTE. LTD. | O11: 8.3272 | P11: =VLOOKUP(L11,[3]BHSC_销售订单明细报表_060825!$E$1:$E$65536,1,FALSE)
A12: 11 | B12: chanhua | C12: 45667 | D12: 新加坡比特 | E12: ASE-KH | H12: BM1370PA | I12: =VLOOKUP(H12,编码对账表!C:D,2,0) | J12: 33395 | K12: 202501130013 | L12: 1403250113115247 | M12: 泰国ONETEC | N12: CHANHUA PTE. LTD. | O12: 8.3272 | P12: =VLOOKUP(L12,[3]BHSC_销售订单明细报表_060825!$E$1:$E$65536,1,FALSE)
A13: 12 | B13: chanhua | C13: 45663 | D13: 新加坡比特 | E13: JSCC | H13: BM1370PA | I13: =VLOOKUP(H13,编码对账表!C:D,2,0) | J13: 1705790 | K13: 202501130013 | L13: 1403250113115247 | M13: 泰国ONETEC | N13: CHANHUA PTE. LTD. | O13: 8.3272 | P13: =VLOOKUP(L13,[3]BHSC_销售订单明细报表_060825!$E$1:$E$65536,1,FALSE)
... A167: 166 | B167: chanhua | C167: 45692 | D167: 新加坡比特 | E167: SPILSZ | H167: BM1370PA | I167: =VLOOKUP(H167,编码对账表!C:D,2,0) | J167: 995658 | K167: 202502060010 | L167: 1403250206114656 | M167: Nationgate | N167: CHANHUA PTE. LTD. | O167: 8.3272 | P167: =VLOOKUP(L167,[3]BHSC_销售订单明细报表_060825!$E$1:$E$65536,1,FALSE)
A168: 167 | B168: chanhua | C168: 45681 | D168: 新加坡比特 | E168: ASECL | H168: BM1370PA | I168: =VLOOKUP(H168,编码对账表!C:D,2,0) | J168: 71 | K168: 202501300101 | L168: 1403250213180648 | M168: 泰国ONETEC | N168: CHANHUA PTE. LTD. | O168: 8.3272 | P168: =VLOOKUP(L168,[3]BHSC_销售订单明细报表_060825!$E$1:$E$65536,1,FALSE) | R168: 下多了，删除
A169: 168 | B169: chanhua | C169: 45681 | D169: 新加坡比特 | E169: ASECL | H169: BM1370PA | I169: =VLOOKUP(H169,编码对账表!C:D,2,0) | J169: 560 | K169: 202501300102 | L169: 1403250213180703 | M169: 泰国群光 | N169: CHANHUA PTE. LTD. | O169: 8.3272 | P169: =VLOOKUP(L169,[3]BHSC_销售订单明细报表_060825!$E$1:$E$65536,1,FALSE)
A170: 169 | B170: chanhua | C170: 45680 | D170: 新加坡比特 | E170: ASECL | H170: BM1370BC | I170: =VLOOKUP(H170,编码对账表!C:D,2,0) | J170: 304 | K170: 202501300103 | L170: 1403250214151516 | M170: 墨西哥欧陆通 | N170: CHANHUA PTE. LTD. | O170: 8.3272 | P170: =VLOOKUP(L170,[3]BHSC_销售订单明细报表_060825!$E$1:$E$65536,1,FALSE)
A171: 170 | B171: chanhua | C171: 45702 | D171: 新加坡比特 | E171: ASE-KH | H171: BM1370PA | I171: =VLOOKUP(H171,[1]编码对账表!C:D,2,0) | J171: 2401 | K171: 202502240010 | L171: 1403250214171119 | M171: 印尼奥海 | N171: CHANHUA PTE. LTD. | O171: 8.3272 | P171: =VLOOKUP(L171,[3]BHSC_销售订单明细报表_060825!$E$1:$E$65536,1,FALSE)
A172: 171 | B172: chanhua | C172: 45699 | D172: 新加坡比特 | E172: ASECL | H172: BM1370PA | I172: =VLOOKUP(H172,[1]编码对账表!C:D,2,0) | J172: 53200 | K172: 202502240010 | L172: 1403250214171119 | M172: 印尼奥海 | N172: CHANHUA PTE. LTD. | O172: 8.3272 | P172: =VLOOKUP(L172,[3]BHSC_销售订单明细报表_060825!$E$1:$E$65536,1,FALSE)
A173: 172 | B173: chanhua | C173: 45698 | D173: 新加坡比特 | E173: JSCC | H173: BM1370PA | I173: =VLOOKUP(H173,[1]编码对账表!C:D,2,0) | J173: 287620 | K173: 202502240010 | L173: 1403250214171119 | M173: 印尼奥海 | N173: CHANHUA PTE. LTD. | O173: 8.3272 | P173: =VLOOKUP(L173,[3]BHSC_销售订单明细报表_060825!$E$1:$E$65536,1,FALSE)
A174: 173 | B174: chanhua | C174: 45699 | D174: 新加坡比特 | E174: SPILSZ | H174: BM1370PA | I174: =VLOOKUP(H174,[1]编码对账表!C:D,2,0) | J174: 1170582 | K174: 202502240010 | L174: 1403250214171119 | M174: 印尼奥海 | N174: CHANHUA PTE. LTD. | O174: 8.3272 | P174: =VLOOKUP(L174,[3]BHSC_销售订单明细报表_060825!$E$1:$E$65536,1,FALSE)
